[2024-11-04T23:58:45.122+0000] {local_task_job_runner.py:123} INFO - ::group::Pre task execution logs
[2024-11-04T23:58:45.150+0000] {taskinstance.py:2612} INFO - Dependencies all met for dep_context=non-requeueable deps ti=<TaskInstance: marketvol.tmp_move_AAPL manual__2024-11-04T23:53:26.624508+00:00 [queued]>
[2024-11-04T23:58:45.163+0000] {taskinstance.py:2612} INFO - Dependencies all met for dep_context=requeueable deps ti=<TaskInstance: marketvol.tmp_move_AAPL manual__2024-11-04T23:53:26.624508+00:00 [queued]>
[2024-11-04T23:58:45.164+0000] {taskinstance.py:2865} INFO - Starting attempt 2 of 3
[2024-11-04T23:58:45.195+0000] {taskinstance.py:2888} INFO - Executing <Task(BashOperator): tmp_move_AAPL> on 2024-11-04 23:53:26.624508+00:00
[2024-11-04T23:58:45.203+0000] {warnings.py:112} WARNING - /home/***/.local/lib/python3.12/site-packages/***/task/task_runner/standard_task_runner.py:70: DeprecationWarning: This process (pid=15925) is multi-threaded, use of fork() may lead to deadlocks in the child.
  pid = os.fork()

[2024-11-04T23:58:45.206+0000] {standard_task_runner.py:72} INFO - Started process 15929 to run task
[2024-11-04T23:58:45.207+0000] {standard_task_runner.py:104} INFO - Running: ['***', 'tasks', 'run', 'marketvol', 'tmp_move_AAPL', 'manual__2024-11-04T23:53:26.624508+00:00', '--job-id', '9', '--raw', '--subdir', 'DAGS_FOLDER/Airflow_Miniproj.py', '--cfg-path', '/tmp/tmpm0pcdug5']
[2024-11-04T23:58:45.209+0000] {standard_task_runner.py:105} INFO - Job 9: Subtask tmp_move_AAPL
[2024-11-04T23:58:45.278+0000] {task_command.py:467} INFO - Running <TaskInstance: marketvol.tmp_move_AAPL manual__2024-11-04T23:53:26.624508+00:00 [running]> on host 2e0e50a1433f
[2024-11-04T23:58:45.415+0000] {taskinstance.py:3131} INFO - Exporting env vars: AIRFLOW_CTX_DAG_OWNER='Margaret' AIRFLOW_CTX_DAG_ID='marketvol' AIRFLOW_CTX_TASK_ID='tmp_move_AAPL' AIRFLOW_CTX_EXECUTION_DATE='2024-11-04T23:53:26.624508+00:00' AIRFLOW_CTX_TRY_NUMBER='2' AIRFLOW_CTX_DAG_RUN_ID='manual__2024-11-04T23:53:26.624508+00:00'
[2024-11-04T23:58:45.417+0000] {logging_mixin.py:190} INFO - Task instance is in running state
[2024-11-04T23:58:45.418+0000] {logging_mixin.py:190} INFO -  Previous state of the Task instance: queued
[2024-11-04T23:58:45.420+0000] {logging_mixin.py:190} INFO - Current task name:tmp_move_AAPL state:running start_date:2024-11-04 23:58:45.150915+00:00
[2024-11-04T23:58:45.421+0000] {logging_mixin.py:190} INFO - Dag name:marketvol and current dag run status:running
[2024-11-04T23:58:45.421+0000] {taskinstance.py:731} INFO - ::endgroup::
[2024-11-04T23:58:45.422+0000] {subprocess.py:63} INFO - Tmp dir root location: /tmp
[2024-11-04T23:58:45.425+0000] {subprocess.py:75} INFO - Running command: ['/usr/bin/bash', '-c', 'mv ./AAPL_data.csv /tmp/data/2024-11-04/']
[2024-11-04T23:58:45.443+0000] {subprocess.py:86} INFO - Output:
[2024-11-04T23:58:45.449+0000] {subprocess.py:93} INFO - mv: cannot stat './AAPL_data.csv': No such file or directory
[2024-11-04T23:58:45.450+0000] {subprocess.py:97} INFO - Command exited with return code 1
[2024-11-04T23:58:45.470+0000] {taskinstance.py:3310} ERROR - Task failed with exception
Traceback (most recent call last):
  File "/home/airflow/.local/lib/python3.12/site-packages/airflow/models/taskinstance.py", line 767, in _execute_task
    result = _execute_callable(context=context, **execute_callable_kwargs)
             ^^^^^^^^^^^^^^^^^^^^^^^^^^^^^^^^^^^^^^^^^^^^^^^^^^^^^^^^^^^^^
  File "/home/airflow/.local/lib/python3.12/site-packages/airflow/models/taskinstance.py", line 733, in _execute_callable
    return ExecutionCallableRunner(
           ^^^^^^^^^^^^^^^^^^^^^^^^
  File "/home/airflow/.local/lib/python3.12/site-packages/airflow/utils/operator_helpers.py", line 252, in run
    return self.func(*args, **kwargs)
           ^^^^^^^^^^^^^^^^^^^^^^^^^^
  File "/home/airflow/.local/lib/python3.12/site-packages/airflow/models/baseoperator.py", line 406, in wrapper
    return func(self, *args, **kwargs)
           ^^^^^^^^^^^^^^^^^^^^^^^^^^^
  File "/home/airflow/.local/lib/python3.12/site-packages/airflow/operators/bash.py", line 249, in execute
    raise AirflowException(
airflow.exceptions.AirflowException: Bash command failed. The command returned a non-zero exit code 1.
[2024-11-04T23:58:45.484+0000] {logging_mixin.py:190} INFO - Task instance in failure state
[2024-11-04T23:58:45.486+0000] {logging_mixin.py:190} INFO - Task start:2024-11-04 23:58:45.150915+00:00 end:2024-11-04 23:58:45.483259+00:00 duration:0.332344
[2024-11-04T23:58:45.487+0000] {logging_mixin.py:190} INFO - Task:<Task(BashOperator): tmp_move_AAPL> dag:<DAG: marketvol> dagrun:<DagRun marketvol @ 2024-11-04 23:53:26.624508+00:00: manual__2024-11-04T23:53:26.624508+00:00, state:running, queued_at: 2024-11-04 23:53:26.683633+00:00. externally triggered: True>
[2024-11-04T23:58:45.488+0000] {logging_mixin.py:190} INFO - Failure caused by Bash command failed. The command returned a non-zero exit code 1.
[2024-11-04T23:58:45.488+0000] {taskinstance.py:1225} INFO - Marking task as UP_FOR_RETRY. dag_id=marketvol, task_id=tmp_move_AAPL, run_id=manual__2024-11-04T23:53:26.624508+00:00, execution_date=20241104T235326, start_date=20241104T235845, end_date=20241104T235845
[2024-11-04T23:58:45.522+0000] {taskinstance.py:340} INFO - ::group::Post task execution logs
[2024-11-04T23:58:45.523+0000] {standard_task_runner.py:124} ERROR - Failed to execute job 9 for task tmp_move_AAPL (Bash command failed. The command returned a non-zero exit code 1.; 15929)
Traceback (most recent call last):
  File "/home/airflow/.local/lib/python3.12/site-packages/airflow/task/task_runner/standard_task_runner.py", line 117, in _start_by_fork
    ret = args.func(args, dag=self.dag)
          ^^^^^^^^^^^^^^^^^^^^^^^^^^^^^
  File "/home/airflow/.local/lib/python3.12/site-packages/airflow/cli/cli_config.py", line 49, in command
    return func(*args, **kwargs)
           ^^^^^^^^^^^^^^^^^^^^^
  File "/home/airflow/.local/lib/python3.12/site-packages/airflow/utils/cli.py", line 115, in wrapper
    return f(*args, **kwargs)
           ^^^^^^^^^^^^^^^^^^
  File "/home/airflow/.local/lib/python3.12/site-packages/airflow/cli/commands/task_command.py", line 483, in task_run
    task_return_code = _run_task_by_selected_method(args, _dag, ti)
                       ^^^^^^^^^^^^^^^^^^^^^^^^^^^^^^^^^^^^^^^^^^^^
  File "/home/airflow/.local/lib/python3.12/site-packages/airflow/cli/commands/task_command.py", line 256, in _run_task_by_selected_method
    return _run_raw_task(args, ti)
           ^^^^^^^^^^^^^^^^^^^^^^^
  File "/home/airflow/.local/lib/python3.12/site-packages/airflow/cli/commands/task_command.py", line 341, in _run_raw_task
    return ti._run_raw_task(
           ^^^^^^^^^^^^^^^^^
  File "/home/airflow/.local/lib/python3.12/site-packages/airflow/utils/session.py", line 97, in wrapper
    return func(*args, session=session, **kwargs)
           ^^^^^^^^^^^^^^^^^^^^^^^^^^^^^^^^^^^^^^
  File "/home/airflow/.local/lib/python3.12/site-packages/airflow/models/taskinstance.py", line 3004, in _run_raw_task
    return _run_raw_task(
           ^^^^^^^^^^^^^^
  File "/home/airflow/.local/lib/python3.12/site-packages/airflow/models/taskinstance.py", line 273, in _run_raw_task
    TaskInstance._execute_task_with_callbacks(
  File "/home/airflow/.local/lib/python3.12/site-packages/airflow/models/taskinstance.py", line 3158, in _execute_task_with_callbacks
    result = self._execute_task(context, task_orig)
             ^^^^^^^^^^^^^^^^^^^^^^^^^^^^^^^^^^^^^^
  File "/home/airflow/.local/lib/python3.12/site-packages/airflow/models/taskinstance.py", line 3182, in _execute_task
    return _execute_task(self, context, task_orig)
           ^^^^^^^^^^^^^^^^^^^^^^^^^^^^^^^^^^^^^^^
  File "/home/airflow/.local/lib/python3.12/site-packages/airflow/models/taskinstance.py", line 767, in _execute_task
    result = _execute_callable(context=context, **execute_callable_kwargs)
             ^^^^^^^^^^^^^^^^^^^^^^^^^^^^^^^^^^^^^^^^^^^^^^^^^^^^^^^^^^^^^
  File "/home/airflow/.local/lib/python3.12/site-packages/airflow/models/taskinstance.py", line 733, in _execute_callable
    return ExecutionCallableRunner(
           ^^^^^^^^^^^^^^^^^^^^^^^^
  File "/home/airflow/.local/lib/python3.12/site-packages/airflow/utils/operator_helpers.py", line 252, in run
    return self.func(*args, **kwargs)
           ^^^^^^^^^^^^^^^^^^^^^^^^^^
  File "/home/airflow/.local/lib/python3.12/site-packages/airflow/models/baseoperator.py", line 406, in wrapper
    return func(self, *args, **kwargs)
           ^^^^^^^^^^^^^^^^^^^^^^^^^^^
  File "/home/airflow/.local/lib/python3.12/site-packages/airflow/operators/bash.py", line 249, in execute
    raise AirflowException(
airflow.exceptions.AirflowException: Bash command failed. The command returned a non-zero exit code 1.
[2024-11-04T23:58:45.542+0000] {local_task_job_runner.py:266} INFO - Task exited with return code 1
[2024-11-04T23:58:45.578+0000] {taskinstance.py:3900} INFO - 0 downstream tasks scheduled from follow-on schedule check
[2024-11-04T23:58:45.582+0000] {local_task_job_runner.py:245} INFO - ::endgroup::
